Workbook
Name AMAZONAS: DatosPruebaEmp!$AE$3:$AE$13
Name ANTIOQUIA: DatosPruebaEmp!$AF$3:$AF$127
Name ARAUCA: DatosPruebaEmp!$AG$3:$AG$9
Name ATLANTICO: DatosPruebaEmp!$AH$3:$AH$25
Name BOGOTA_D.E.: DatosPruebaEmp!$AI$3
Name BOLIVAR: DatosPruebaEmp!$AJ$3:$AJ$48
Name BOYACA: DatosPruebaEmp!$AK$3:$AK$125
Name CALDAS: DatosPruebaEmp!$AL$3:$AL$29
Name CAQUETA: DatosPruebaEmp!$AM$3:$AM$18
Name CASANARE: DatosPruebaEmp!$AN$3:$AN$21
Name CAUCA: DatosPruebaEmp!$AO$3:$AO$44
Name CESAR: DatosPruebaEmp!$AP$3:$AP$27
Name CHOCO: DatosPruebaEmp!$AQ$3:$AQ$32
Name CORDOBA: DatosPruebaEmp!$AR$3:$AR$32
Name CUNDINAMARCA: DatosPruebaEmp!$AS$3:$AS$118
Name Encabezados: #REF!
Name GUAINIA: DatosPruebaEmp!$AT$3:$AT$11
Name GUAVIARE: DatosPruebaEmp!$AU$3:$AU$6
Name HUILA: DatosPruebaEmp!$AV$3:$AV$39
Name LA_GUAJIRA: DatosPruebaEmp!$AW$3:$AW$17
Name MAGDALENA: DatosPruebaEmp!$AX$3:$AX$32
Name META: DatosPruebaEmp!$AY$3:$AY$31
Name NARIÑO: DatosPruebaEmp!$AZ$3:$AZ$66
Name NORTE_DE_SANTANDER: DatosPruebaEmp!$BA$3:$BA$42
Name PUTUMAYO: DatosPruebaEmp!$BB$3:$BB$15
Name QUINDIO: DatosPruebaEmp!$BC$3:$BC$14
Name RGAFP: DatosPruebaEmp!$G$3:$G$12
Name RGALTORIESGO: DatosPruebaEmp!$P$3:$P$9
Name RGARP: DatosPruebaEmp!$K$3:$K$14
Name RGCCF: DatosPruebaEmp!$J$3:$J$46
Name RGCENTRABAJO: DatosPruebaEmp!$B$3:$B$27
Name RGCLASERIESGO: DatosPruebaEmp!$L$3
Name RGDIVIDEPTO: DatosPruebaEmp!$AD$3:$AD$35
Name RGEPS: DatosPruebaEmp!$I$3:$I$47
Name RGETIQUETAS: DatosPruebaEmp!$BR$3
Name RGGRUPOPOB: DatosPruebaEmp!$AC$3:$AC$16
Name RGINDALTORIESGO: DatosPruebaEmp!$H$3:$H$7
Name RGNOVEDADES: DatosPruebaEmp!$BO$3:$BO$15
Name RGNOVEDADSLN: DatosPruebaEmp!$W$3:$W$5
Name RGNOVEDADSLN2: DatosPruebaEmp!$X$3:$X$4
Name RGNOVEDADVAC: DatosPruebaEmp!$BN$3:$BN$5
Name RGSINO: DatosPruebaEmp!$M$3:$M$4
Name RGSINOVACIO: DatosPruebaEmp!$N$3:$N$5
Name RGSUBTIPOSCOT: DatosPruebaEmp!$F$3:$F$13
Name RGSUCURSALES: DatosPruebaEmp!$A$3:$A$9
Name RGTARIFAARL: DatosPruebaEmp!$Q$3:$Q$8
Name RGTARIFAARL2: DatosPruebaEmp!$R$3:$R$8
Name RGTARIFAPENSION: DatosPruebaEmp!$Y$3:$Y$4
Name RGTARIFASCCF: DatosPruebaEmp!$O$3:$O$6
Name RGTIPOCORRECCIONES: DatosPruebaEmp!$V$3:$V$5
Name RGTIPOING: DatosPruebaEmp!$AA$3:$AA$4
Name RGTIPOINGLIQ: DatosPruebaEmp!$BL$3:$BL$6
Name RGTIPOPRESENTACION: DatosPruebaEmp!$BP$3:$BP$6
Name RGTIPORET: DatosPruebaEmp!$AB$3:$AB$6
Name RGTIPORETLIQ: DatosPruebaEmp!$BM$3:$BM$7
Name RGTIPOSAPORTANTES: DatosPruebaEmp!$D$3:$D$10
Name RGTIPOSCOT: DatosPruebaEmp!$E$3:$E$38
Name RGTIPOSDOCS: DatosPruebaEmp!$S$3:$S$11
Name RGTIPOSDOCSNIT: DatosPruebaEmp!$T$3:$T$11
Name RGTIPOSNOVINGRET: DatosPruebaEmp!$U$3:$U$4

Sheet DatosPruebaEmp
A1: 0-CENTRO TRABAJO 0 | B1: 1-CENTRO TRABAJO 1 | C1: 10-CENTRO TRABAJO 10 | D1: 15-CENTRO TRABAJO 15 | E1: 24-CENTRO TRABAJO 24 | F1: 3-CENTRO TRABAJO 3 | G1: 30-CENTRO TRABAJO 30 | H1: 33-CENTRO TRABAJO 33 | I1: 4-CENTRO TRABAJO 4 | J1: 40-CENTRO TRABAJO 40 | K1: 50-CENTRO TRABAJO 50 | L1: 57-CENTRO TRABAJO 57 | M1: 6-CENTRO TRABAJO 6 | N1: 67-CENTRO TRABAJO 67 | O1: 696-CENTRO TRABAJO 696 | P1: 8-CENTRO TRABAJO 8 | Q1: 01-PRINCIPAL | R1: 2-ROSAL | S1: 33-CAJAMAG | T1: 31-GUA | U1: 1-RIESGO 01 | V1: 696-RIESGO 5 | W1: 04-SANTANDER | X1: 50-CENTRO 05 | Y1: 05-OBRA
A3: NINGUNA | B3: CENTRO TRABAJO 0 | C3: E - Planilla Empleados Empresas | D3: EMPLEADOR | E3: 1. DEPENDIENTE | F3: NINGUNO | G3: NINGUNA | H3: Sin Riesgo | I3: NINGUNA | J3: NINGUNA | K3: NINGUNA | L3: NINGUNA | M3: NO | N3: NO | O3: NINGUNA | P3: SIN RIESGO | Q3: NINGUNA | R3: 0 | S3: CC | T3: CC | U3: INGRESO (ING) | V3: ACTUAL | W3: NO | X3: LICENCIA NO REMUNERADA | Y3: TARIFA DEL EMPLEADOR | Z3: VARIACIÓN PERMANENTE DE SALARIO (VSP) | AA3: Todos los sistemas (ARL, AFP, CCF, EPS) | AB3: Todos los sistemas (ARL, AFP, CCF, EPS) | AC3: NINGUNO | AD3: AMAZONAS | AE3: EL ENCANTO | AF3: ABEJORRAL | AG3: ARAUCA | AH3: BARANOA | AI3: BOGOTA | AJ3: ACHI | AK3: ALMEIDA | AL3: AGUADAS | AM3: ALBANIA | AN3: AGUAZUL | AO3: ALMAGUER | AP3: AGUACHICA | AQ3: ACANDI | AR3: AYAPEL | AS3: AGUA DE DIOS | AT3: BARRANCO MINAS | AU3: CALAMAR | AV3: ACEVEDO | AW3: ALBANIA | AX3: ALGARROBO | AY3: ACACIAS | AZ3: ALBAN | BA3: ABREGO | BB3: COLON | BC3: ARMENIA | BD3: APIA | BE3: PROVIDENCIA | BF3: AGUADA | BG3: BUENAVISTA | BH3: ALPUJARRA | BI3: ALCALA | BJ3: CARURU | BK3: CUMARIBO | BL3: Todos los sistemas (ARL, AFP, CCF, EPS) | BM3: Todos los sistemas (ARL, AFP, CCF, EPS) | BN3: VACACIONES | BO3: INCAPACIDAD GENERAL (IGE) | BP3: SUCURSAL | BQ3: VACACIONES | BR3: NINGUNA
A4: PRINCIPAL | B4: CENTRO TRABAJO 1 | C4: A - Planilla Empleados Adicionales | D4: INDEPENDIENTE | E4: 12. APRENDICES EN ETAPA LECTIVA | F4: 1. DEPENDIENTE PENSIONADO ACTIVO | G4: CAXDAC | H4: 1. Actividades de alto riesgo | I4: A.I.C. | J4: CAFABA | K4: ALFA | M4: SI | N4: SI | O4: 0.006 | P4: ALTO RIESGO | Q4: 0.00522 | R4: 0.00522 | S4: CE | T4: CE | U4: RETIRO DE LA EMPRESA (RET) | V4: CORRECCIÓN | W4: LICENCIA NO REMUNERADA | X4: COMISIÓN DE SERVICIO | Y4: TARIFA TOTAL | Z4: VARIACIÓN TRANSITORIA DE SALARIO (VST) | AA4: Administradora de Riesgos Laborales (ARL) | AB4: Administradora de Fondo de Pensiones (AFP) | AC4: CONCEJALES I | AD4: ANTIOQUIA | AE4: LA CHORRERA | AF4: ABRIAQUI | AG4: ARAUQUITA | AH4: BARRANQUILLA | AJ4: ALTOS DEL ROSARIO | AK4: AQUITANIA | AL4: ANSERMA | AM4: BELEN DE LOS ANDAQUIES | AN4: CHAMEZA | AO4: ARGELIA | AP4: AGUSTIN CODAZZI | AQ4: ALTO BAUDO | AR4: BUENAVISTA | AS4: ALBAN | AT4: CACAHUAL | AU4: EL RETORNO | AV4: AGRADO | AW4: BARRANCAS | AX4: ARACATACA | AY4: BARRANCA DE UPIA | AZ4: ALDANA | BA4: ARBOLEDAS | BB4: LEGUIZAMO | BC4: BUENAVISTA | BD4: BALBOA | BE4: SAN ANDRES | BF4: ALBANIA | BG4: CAIMITO | BH4: ALVARADO | BI4: ANDALUCIA | BJ4: MITU | BK4: LA PRIMAVERA | BL4: Administradora de Riesgos Laborales (ARL) | BM4: Administradora de Fondo de Pensiones (AFP) | BN4: LICENCIA REMUNERADA | BO4: INCAPACIDAD LABORAL (IRL) | BP4: ÚNICA | BQ4: LICENCIA REMUNERADA
A5: CAJAMAG | B5: CENTRO TRABAJO 10 | C5: I - Planilla Independientes | D5: ENTIDADES O UNIVERSIDADES PÚBLICAS CON RÉGIMEN ESPECIAL EN SALUD | E5: 15. DESEMPLEADO CON SUBSIDIO DE CAJA DE COMPENSACIÓN FAMILIAR | F5: 2. INDEPENDIENTE PENSIONADO ACTIVO | G5: COLFONDOS | H5: 2. Senadores | I5: ADRES - CONTRIBUCIÓN SOLIDARIA | J5: CAFAM | K5: ARL SURA | O5: 0.02 | P5: CTI | Q5: 0.01044 | R5: 0.01044 | S5: TI | T5: NIT | V5: NO | W5: COMISIÓN DE SERVICIO | AB5: Administradora de Riesgos Laborales (ARL) | AC5: CONCEJALES II | AD5: ARAUCA | AE5: LA PEDRERA | AF5: ALEJANDRIA | AG5: CRAVO NORTE | AH5: CAMPO DE LA CRUZ | AJ5: ARENAL | AK5: ARCABUCO | AL5: ARANZAZU | AM5: CARTAGENA DEL CHAIRA | AN5: HATO COROZAL | AO5: BALBOA | AP5: ASTREA | AQ5: ATRATO | AR5: CANALETE | AS5: ANAPOIMA | AT5: INIRIDA | AU5: MIRAFLORES | AV5: AIPE | AW5: DIBULLA | AX5: ARIGUANI | AY5: CABUYARO | AZ5: ANCUYA | BA5: BOCHALEMA | BB5: MOCOA | BC5: CALARCA | BD5: BELEN DE UMBRIA | BF5: ARATOCA | BG5: CHALAN | BH5: AMBALEMA | BI5: ANSERMANUEVO | BJ5: PACOA | BK5: PUERTO CARREÑO | BL5: Caja de Compensación Familiar (CCF) | BM5: Administradora de Riesgos Laborales (ARL) | BN5: NO | BO5: INGRESO (ING) | BP5: CONSOLIDADO
A6: GUAJIRA | B6: CENTRO TRABAJO 15 | C6: Y - Planilla Independientes Empresas | D6: COOPERATIVA Y PRE COOPERATIVA DE TRABAJO ASOCIADO | E6: 16. INDEPENDIENTE AGREMIADO O ASOCIADO | F6: 3. COTIZANTE NO OBLIGADO A COTIZACIÓN A PENSIONES POR EDAD | G6: COLPENSIONES | H6: 3. CTI | I6: ALIANSALUD EPS (ANTES COLMEDICA) | J6: CAFAMAZ | K6: COLMENA | O6: 0.04 | P6: ALTO RIESGO (6%) | Q6: 0.02436 | R6: 0.02436 | S6: RC | T6: TI | AB6: Caja de Compensación Familiar (CCF) | AC6: DESEMPLEADOS | AD6: ATLANTICO | AE6: LA VICTORIA | AF6: AMAGA | AG6: FORTUL | AH6: CANDELARIA | AJ6: ARJONA | AK6: BELEN | AL6: BELALCAZAR | AM6: CURILLO | AN6: LA SALINA | AO6: BOLIVAR | AP6: BECERRIL | AQ6: BAGADO | AR6: CERETE | AS6: ANOLAIMA | AT6: LA GUADALUPE | AU6: SAN JOSE DEL GUAVIARE | AV6: ALGECIRAS | AW6: DISTRACCION | AX6: CERRO SAN ANTONIO | AY6: CASTILLA LA NUEVA | AZ6: ARBOLEDA | BA6: BUCARASICA | BB6: ORITO | BC6: CIRCASIA | BD6: DOSQUEBRADAS | BF6: BARBOSA | BG6: COLOSO | BH6: ANZOATEGUI | BI6: ARGELIA | BJ6: PAPUNAUA | BK6: SANTA ROSALIA | BL6: NO | BM6: Caja de Compensación Familiar (CCF) | BO6: INICIO RESIDENCIA EN EL EXTERIOR (IRE) | BP6: DEPENDENCIA
A7: MEDELLIN | B7: CENTRO TRABAJO 24 | C7: S - Planilla Empleados de Independientes | D7: MISIÓN DIPLOMÁTICA | E7: 18. FUNCIONARIOS PÚBLICOS SIN TOPE MÁXIMO EN EL IBC | F7: 4. COTIZANTE CON REQUISITOS CUMPLIDOS PARA PENSIÓN | G7: FONPRECON | H7: 4. Aviadores | I7: ANAS WAYUU | J7: CAFASUR | K7: COLPATRIA ARP | P7: ALTO RIESGO (8.5%) | Q7: 0.0435 | R7: 0.0435 | S7: PA | T7: RC | AC7: DESOCUPADOS | AD7: BOGOTA_D.E. | AE7: LETICIA | AF7: AMALFI | AG7: PUERTO RONDON | AH7: GALAPA | AJ7: ARROYOHONDO | AK7: BERBEO | AL7: CHINCHINA | AM7: EL DONCELLO | AN7: MANI | AO7: BUENOS AIRES | AP7: BOSCONIA | AQ7: BAHIA SOLANO | AR7: CHIMA | AS7: APULO | AT7: MAPIRIPANA | AV7: ALTAMIRA | AW7: EL MOLINO | AX7: CHIBOLO | AY7: CUBARRAL | AZ7: BARBACOAS | BA7: CACHIRA | BB7: PUERTO ASIS | BC7: CORDOBA | BD7: GUATICA | BF7: BARICHARA | BG7: COROZAL | BH7: ARMERO | BI7: BOLIVAR | BJ7: TARAIRA | BM7: NO | BO7: LICENCIA DE MATERNIDAD (LMA)
A8: SANTANDER | B8: CENTRO TRABAJO 3 | C8: N - Planilla Correcciones | D8: ORGANIZACIÓN ADMINISTRADORA DEL PROGRAMA DE HOGARES DE BIENESTAR | E8: 19. APRENDICES EN ETAPA PRODUCTIVA | F8: 5. COTIZANTE CON INDEMNIZACIÓN SUSTITUTIVA O DEVOLUCIÓN DE SALDOS | G8: PENSIONES DE ANTIOQUIA | I8: ASMET SALUD EPS SAS | J8: CAJACOPI ATLANTICO | K8: COLSANITAS ARL | P8: AVIADORES | Q8: 0.0696 | R8: 0.0696 | S8: CD | T8: PA | AC8: DISCAPACITADOS | AD8: BOLIVAR | AE8: MIRITI - PARANA | AF8: ANDES | AG8: SARAVENA | AH8: JUAN DE ACOSTA | AJ8: BARRANCO DE LOBA | AK8: BETEITIVA | AL8: FILADELFIA | AM8: EL PAUJIL | AN8: MONTERREY | AO8: CAJIBIO | AP8: CHIMICHAGUA | AQ8: BAJO BAUDO | AR8: CHINU | AS8: ARBELAEZ | AT8: MORICHAL | AV8: BARAYA | AW8: FONSECA | AX8: CIENAGA | AY8: CUMARAL | AZ8: BELEN | BA8: CACOTA | BB8: PUERTO CAICEDO | BC8: FILANDIA | BD8: LA CELIA | BF8: BARRANCABERMEJA | BG8: COVEÑAS | BH8: ATACO | BI8: BUENAVENTURA | BJ8: YAVARATE | BO8: RETIRO DE LA EMPRESA (RET)
A9: TOLIMA | B9: CENTRO TRABAJO 30 | C9: M - Planilla Mora | D9: AGREMIACIÓN O ASOCIACIÓN | E9: 20. ESTUDIANTES | F9: 6. COTIZANTE PERTENECIENTE A UN RÉGIMEN EXCEPTUADO DE PENSIONES | G9: PORVENIR | I9: CAJACOPI ATLANTICO | J9: CAJAMAG | K9: FONDO DE RIESGOS LABORALES | P9: SENADORES | S9: SC | T9: CD | AC9: INDEPENDIENTES RURALES I | AD9: BOYACA | AE9: PUERTO ALEGRIA | AF9: ANGELOPOLIS | AG9: TAME | AH9: LURUACO | AJ9: CALAMAR | AK9: BOAVITA | AL9: LA DORADA | AM9: FLORENCIA | AN9: NUNCHIA | AO9: CALDONO | AP9: CHIRIGUANA | AQ9: BOJAYA | AR9: CIENAGA DE ORO | AS9: BELTRAN | AT9: PANA PANA | AV9: CAMPOALEGRE | AW9: HATONUEVO | AX9: CONCORDIA | AY9: EL CALVARIO | AZ9: BUESACO | BA9: CHINACOTA | BB9: PUERTO GUZMAN | BC9: GENOVA | BD9: LA VIRGINIA | BF9: BETULIA | BG9: EL ROBLE | BH9: CAJAMARCA | BI9: BUGALAGRANDE | BO9: SUSPENSIÓN TEMPORAL DEL CONTRATO DE TRABAJO (SLN)
B10: CENTRO TRABAJO 33 | C10: H - Plantilla Madres Comunitarias | D10: PAGADOR DE APORTES DE LOS CONCEJALES O EDILES | E10: 21. ESTUDIANTE Y RESIDENTE | F10: 9. PENSIONADO CON MESADA IGUAL A 25 SMLMV | G10: PROTECCION | I10: CAPITAL SALUD | J10: CAJASAI | K10: LA EQUIDAD SEGUROS | S10: PE | T10: PE | AC10: INDEPENDIENTES RURALES II | AD10: CALDAS | AE10: PUERTO ARICA | AF10: ANGOSTURA | AH10: MALAMBO | AJ10: CANTAGALLO | AK10: BOYACA | AL10: LA MERCED | AM10: LA MONTAÑITA | AN10: OROCUE | AO10: CALOTO | AP10: CURUMANI | AQ10: CARMEN DEL DARIEN | AR10: COTORRA | AS10: BITUIMA | AT10: PUERTO COLOMBIA | AV10: COLOMBIA | AW10: LA JAGUA DEL PILAR | AX10: EL BANCO | AY10: EL CASTILLO | AZ10: CHACHAGI | BA10: CHITAGA | BB10: SAN FRANCISCO | BC10: LA TEBAIDA | BD10: MARSELLA | BF10: BOLIVAR | BG10: GALERAS | BH10: CARMEN DE APICALA | BI10: CAICEDONIA | BO10: TIEMPO PARCIAL (TPR)
B11: CENTRO TRABAJO 4 | C11: T - Planilla Sistema General de Participación | E11: 22. PROFESOR DE ESTABLECIMIENTO PARTICULAR | F11: 10. COLOMBIANO RESIDENTE EN EL EXTERIOR | G11: SKANDIA | I11: CAPRESOCA | J11: CAJASAN | K11: MAPFRE COLOMBIA VIDA SEGUROS S.A. | S11: PT | T11: PT | AC11: INDEPENDIENTES RURALES III | AD11: CAQUETA | AE11: PUERTO NARIÑO | AF11: ANORI | AH11: MANATI | AJ11: CARTAGENA | AK11: BRICEÑO | AL11: MANIZALES | AM11: MILAN | AN11: PAZ DE ARIPORO | AO11: CORINTO | AP11: EL COPEY | AQ11: CERTEGUI | AR11: LA APARTADA | AS11: BOJACA | AT11: SAN FELIPE | AV11: ELIAS | AW11: MAICAO | AX11: EL PIÑON | AY11: EL DORADO | AZ11: COLON | BA11: CONVENCION | BB11: SAN MIGUEL | BC11: MONTENEGRO | BD11: MISTRATO | BF11: BUCARAMANGA | BG11: GUARANDA | BH11: CASABIANCA | BI11: CALI | BO11: VACACIONES (VAC)
B12: CENTRO TRABAJO 40 | C12: F - Planilla Faltante SGP | E12: 23. ESTUDIANTES DECRETO 055 | F12: 11. TAXISTA | G12: SKANDIA ALTERNATIVO | I12: COMFACHOCÓ | J12: COFREM | K12: POSITIVA COMPAÑIA DE SEGUROS | AC12: INDEPENDIENTES URBANOS I | AD12: CASANARE | AE12: PUERTO SANTANDER | AF12: ANZA | AH12: PALMAR DE VARELA | AJ12: CICUCO | AK12: BUENAVISTA | AL12: MANZANARES | AM12: MORELIA | AN12: PORE | AO12: EL TAMBO | AP12: EL PASO | AQ12: CONDOTO | AR12: LORICA | AS12: CABRERA | AV12: GARZON | AW12: MANAURE | AX12: EL RETEN | AY12: FUENTE DE ORO | AZ12: CONSACA | BA12: CUCUTA | BB12: SANTIAGO | BC12: PIJAO | BD12: PEREIRA | BF12: CABRERA | BG12: LA UNION | BH12: CHAPARRAL | BI12: CALIMA | BO12: VARIACIÓN HORAS LABORADAS (VHL)
B13: CENTRO TRABAJO 50 | C13: J - Planilla Aportes en Sentencia Judicial | E13: 3. INDEPENDIENTE | F13: 12. TAXISTA NO OBLIGADOS A COTIZAR PENSIÓN | I13: COMFAMILIAR GUAJIRA | J13: COLSUBSIDIO | K13: SEGUROS BOLIVAR | AC13: INDEPENDIENTES URBANOS II | AD13: CAUCA | AE13: TARAPACA | AF13: APARTADO | AH13: PIOJO | AJ13: CLEMENCIA | AK13: BUSBANZA | AL13: MARMATO | AM13: PUERTO RICO | AN13: RECETOR | AO13: FLORENCIA | AP13: GAMARRA | AQ13: EL CANTON DEL SAN PABLO | AR13: LOS CORDOBAS | AS13: CACHIPAY | AV13: GIGANTE | AW13: RIOHACHA | AX13: FUNDACION | AY13: GRANADA | AZ13: CONTADERO | BA13: CUCUTILLA | BB13: SIBUNDOY | BC13: QUIMBAYA | BD13: PUEBLO RICO | BF13: CALIFORNIA | BG13: LOS PALMITOS | BH13: COELLO | BI13: CANDELARIA | BO13: VARIACIÓN IBC PARAFISCALES (VIP)
B14: CENTRO TRABAJO 57 | C14: X – Planilla para el pago de empresa liquidada | E14: 30. DEPENDIENTE ENTIDADES O UNIVERSIDADES PÚBLICAS CON RÉGIMEN ESPECIAL EN SALUD | I14: COMFAMILIAR HUILA | J14: COMBARRANQUILLA | K14: SEGUROS DE VIDA AURORA | AC14: INDEPENDIENTES URBANOS III | AD14: CESAR | AF14: ARBOLETES | AH14: POLONUEVO | AJ14: CORDOBA | AK14: CALDAS | AL14: MARQUETALIA | AM14: SAN JOSE DEL FRAGUA | AN14: SABANALARGA | AO14: GUACHENÉ | AP14: GONZALEZ | AQ14: EL CARMEN DE ATRATO | AR14: MOMIL | AS14: CAJICA | AV14: GUADALUPE | AW14: SAN JUAN DEL CESAR | AX14: GUAMAL | AY14: GUAMAL | AZ14: CORDOBA | BA14: DURANIA | BB14: VALLE DEL GUAMUEZ | BC14: SALENTO | BD14: QUINCHIA | BF14: CAPITANEJO | BG14: MAJAGUAL | BH14: COYAIMA | BI14: CARTAGO | BO14: VARIACIÓN PERMANENTE DE SALARIO (VSP)
B15: CENTRO TRABAJO 6 | C15: K - Planilla Estudiantes | E15: 31. COOPERADO | I15: COMFAMILIAR NARIÑO | J15: COMCAJA | AC15: MADRE COMUNITARIA | AD15: CHOCO | AF15: ARGELIA | AH15: PONEDERA | AJ15: EL CARMEN DE BOLIVAR | AK15: CAMPOHERMOSO | AL15: MARULANDA | AM15: SAN VICENTE DEL CAGUAN | AN15: SACAMA | AO15: GUAPI | AP15: LA GLORIA | AQ15: EL LITORAL DEL SAN JUAN | AR15: MOÑITOS | AS15: CAPARRAPI | AV15: HOBO | AW15: URIBIA | AX15: NUEVA GRANADA | AY15: LA MACARENA | AZ15: CUASPUD | BA15: EL CARMEN | BB15: VILLAGARZON | BD15: SANTA ROSA DE CABAL | BF15: CARCASI | BG15: MORROA | BH15: CUNDAY | BI15: DAGUA | BO15: VARIACIÓN TRANSITORIA DE SALARIO (VST)
B16: CENTRO TRABAJO 67 | C16: O - Obligaciones Determinadas Por La UGPP | E16: 32. DIPLOMÁTICO, CONSULAR O FUNCIONARIO NO SOMETIDO A LEGISLACIÓN COLOMBIANA | I16: COMFAORIENTE | J16: COMFABOY | AC16: CONCEJALES III | AD16: CORDOBA | AF16: ARMENIA | AH16: PUERTO COLOMBIA | AJ16: EL GUAMO | AK16: CERINZA | AL16: NEIRA | AM16: SOLANO | AN16: SAN LUIS DE PALENQUE | AO16: INZA | AP16: LA JAGUA DE IBIRICO | AQ16: ISTMINA | AR16: MONTELIBANO | AS16: CAQUEZA | AV16: IQUIRA | AW16: URUMITA | AX16: PEDRAZA | AY16: LEJANIAS | AZ16: CUMBAL | BA16: EL TARRA | BD16: SANTUARIO | BF16: CEPITA | BG16: OVEJAS | BH16: DOLORES | BI16: EL AGUILA
B17: CENTRO TRABAJO 696 | C17: B - Piso Protección Total | E17: 34. CONCEJAL O EDIL DE BOGOTÁ D.C. | I17: COMFENALCO VALLE | J17: COMFACA | AD17: CUNDINAMARCA | AF17: BARBOSA | AH17: REPELON | AJ17: EL PEÑON | AK17: CHINAVITA | AL17: NORCASIA | AM17: SOLITA | AN17: TAMARA | AO17: JAMBALO | AP17: LA PAZ | AQ17: JURADO | AR17: MONTERIA | AS17: CARMEN DE CARUPA | AV17: ISNOS | AW17: VILLANUEVA | AX17: PIJIÑO DEL CARMEN | AY17: MAPIRIPAN | AZ17: CUMBITARA | BA17: EL ZULIA | BF17: CERRITO | BG17: PALMITO | BH17: ESPINAL | BI17: EL CAIRO
B18: CENTRO TRABAJO 8 | E18: 35. CONCEJAL NO AMPARADO CON PÓLIZA DE SALUD | I18: COMPARTA | J18: COMFACASANARE | AD18: GUAINIA | AF18: BELLO | AH18: SABANAGRANDE | AJ18: HATILLO DE LOBA | AK18: CHIQUINQUIRA | AL18: PACORA | AM18: VALPARAISO | AN18: TAURAMENA | AO18: LA SIERRA | AP18: MANAURE | AQ18: LLORO | AR18: PLANETA RICA | AS18: CHAGUANI | AV18: LA ARGENTINA | AX18: PIVIJAY | AY18: MESETAS | AZ18: EL CHARCO | BA18: GRAMALOTE | BF18: CHARALA | BG18: SAMPUES | BH18: FALAN | BI18: EL CERRITO
B19: PRINCIPAL | E19: 36. EDIL SIN PÓLIZA DE SALUD BENEFICIARIO DEL FSP | I19: COMPENSAR | J19: COMFACAUCA | AD19: GUAVIARE | AF19: BELMIRA | AH19: SABANALARGA | AJ19: MAGANGUE | AK19: CHIQUIZA | AL19: PALESTINA | AN19: TRINIDAD | AO19: LA VEGA | AP19: PAILITAS | AQ19: MEDIO ATRATO | AR19: PUEBLO NUEVO | AS19: CHIA | AV19: LA PLATA | AX19: PLATO | AY19: PUERTO CONCORDIA | AZ19: EL PEÑOL | BA19: HACARI | BF19: CHARTA | BG19: SAN BENITO ABAD | BH19: FLANDES | BI19: EL DOVIO
B20: ROSAL | E20: 4. MADRE SUSTITUTA | I20: CONVIDA | J20: COMFACESAR | AD20: HUILA | AF20: BETANIA | AH20: SANTA LUCIA | AJ20: MAHATES | AK20: CHISCAS | AL20: PENSILVANIA | AN20: VILLANUEVA | AO20: LOPEZ | AP20: PELAYA | AQ20: MEDIO BAUDO | AR20: PUERTO ESCONDIDO | AS20: CHIPAQUE | AV20: NATAGA | AX20: PUEBLOVIEJO | AY20: PUERTO GAITAN | AZ20: EL ROSARIO | BA20: HERRAN | BF20: CHIMA | BG20: SAN JUAN DE BETULIA | BH20: FRESNO | BI20: FLORIDA
B21: CAJAMAG | E21: 40. BENEFICIARIO DE UPC ADICIONAL | I21: COOMEVA | J21: COMFACHOCÓ | AD21: LA_GUAJIRA | AF21: BETULIA | AH21: SANTO TOMAS | AJ21: MARGARITA | AK21: CHITA | AL21: RIOSUCIO | AN21: YOPAL | AO21: MERCADERES | AP21: PUEBLO BELLO | AQ21: MEDIO SAN JUAN | AR21: PUERTO LIBERTADOR | AS21: CHOACHI | AV21: NEIVA | AX21: REMOLINO | AY21: PUERTO LLERAS | AZ21: EL TABLON DE GOMEZ | BA21: LA ESPERANZA | BF21: CHIPATA | BG21: SAN MARCOS | BH21: GUAMO | BI21: GINEBRA
B22: GUA | E22: 43. COTIZANTE VOLUNTARIO A PENSIONES CON PAGO POR TERCERO | I22: COOSALUD EPS | J22: COMFACOR | AD22: MAGDALENA | AF22: BRICEÑO | AH22: SOLEDAD | AJ22: MARIA LA BAJA | AK22: CHITARAQUE | AL22: RISARALDA | AO22: MIRANDA | AP22: RIO DE ORO | AQ22: NOVITA | AR22: PURISIMA | AS22: CHOCONTA | AV22: OPORAPA | AX22: SABANAS DE SAN ANGEL | AY22: PUERTO LOPEZ | AZ22: EL TAMBO | BA22: LA PLAYA | BF22: CIMITARRA | BG22: SAN ONOFRE | BH22: HERVEO | BI22: GUACARI
B23: RIESGO 01 | E23: 44. EMPLEO DE EMERGENCIA MAYOR A UN MES | I23: COOSALUD MOVILIDAD | J23: COMFACUNDI | AD23: META | AF23: BURITICA | AH23: SUAN | AJ23: MOMPOS | AK23: CHIVATA | AL23: SALAMINA | AO23: MORALES | AP23: SAN ALBERTO | AQ23: NUQUI | AR23: SAHAGUN | AS23: COGUA | AV23: PAICOL | AX23: SALAMINA | AY23: PUERTO RICO | AZ23: FRANCISCO PIZARRO | BA23: LABATECA | BF23: CONCEPCION | BG23: SAN PEDRO | BH23: HONDA | BI23: GUADALAJARA DE BUGA
B24: RIESGO 5 | E24: 45. EMPLEO DE EMERGENCIA MENOR A UN MES | I24: DUSAKAWI | J24: COMFAMA | AD24: NARIÑO | AF24: CACERES | AH24: TUBARA | AJ24: MONTECRISTO | AK24: CHIVOR | AL24: SAMANA | AO24: PADILLA | AP24: SAN DIEGO | AQ24: QUIBDO | AR24: SAN ANDRES SOTAVENTO | AS24: COTA | AV24: PALERMO | AX24: SAN SEBASTIAN DE BUENAVISTA | AY24: RESTREPO | AZ24: FUNES | BA24: LOS PATIOS | BF24: CONFINES | BG24: SANTIAGO DE TOLU | BH24: IBAGUE | BI24: JAMUNDI
B25: SANTANDER | E25: 47. DEPENDIENTE BENEFICIARIO DEL SISTEMA GENERAL DE PARTICIPACIONES | I25: EMPRESAS PUBLICAS DE MEDELLIN DEPARTAMENTO MEDICO | J25: COMFAMILIAR ATLANTICO | AD25: NORTE_DE_SANTANDER | AF25: CAICEDO | AH25: USIACURI | AJ25: MORALES | AK25: CIENEGA | AL25: SAN JOSE | AO25: PAEZ | AP25: SAN MARTIN | AQ25: RIO IRO | AR25: SAN ANTERO | AS25: CUCUNUBA | AV25: PALESTINA | AX25: SAN ZENON | AY25: SAN CARLOS DE GUAROA | AZ25: GUACHUCAL | BA25: LOURDES | BF25: CONTRATACION | BG25: SINCE | BH25: ICONONZO | BI25: LA CUMBRE
B26: CENTRO 05 | E26: 51. TRABAJADOR DE TIEMPO PARCIAL | I26: EMSSANAR | J26: COMFAMILIAR CAMACOL | AD26: PUTUMAYO | AF26: CALDAS | AJ26: NOROSI | AK26: COMBITA | AL26: SUPIA | AO26: PATIA | AP26: TAMALAMEQUE | AQ26: RIO QUITO | AR26: SAN BERNARDO DEL VIENTO | AS26: EL COLEGIO | AV26: PITAL | AX26: SANTA ANA | AY26: SAN JUAN DE ARAMA | AZ26: GUAITARILLA | BA26: MUTISCUA | BF26: COROMORO | BG26: SINCELEJO | BH26: LERIDA | BI26: LA UNION
B27: OBRA | E27: 52. BENEFICIARIO DEL MECANISMO DE PROTECCIÓN AL CESANTE | I27: EPS ECOOPSOS S.A.S | J27: COMFAMILIAR CARTAGENA | AD27: QUINDIO | AF27: CAMPAMENTO | AJ27: PINILLOS | AK27: COPER | AL27: VICTORIA | AO27: PIAMONTE | AP27: VALLEDUPAR | AQ27: RIOSUCIO | AR27: SAN CARLOS | AS27: EL PEÑON | AV27: PITALITO | AX27: SANTA BARBARA DE PINTO | AY27: SAN JUANITO | AZ27: GUALMATAN | BA27: OCAÑA | BF27: CURITI | BG27: SUCRE | BH27: LIBANO | BI27: LA VICTORIA
E28: 53. AFILIADO PARTICIPE | I28: EPS FAMILIAR DE COLOMBIA SAS | J28: COMFAMILIAR GUAJIRA | AD28: RISARALDA | AF28: CAÑASGORDAS | AJ28: REGIDOR | AK28: CORRALES | AL28: VILLAMARIA | AO28: PIENDAMO | AQ28: SAN JOSE DEL PALMAR | AR28: SAN JOSE DE URE | AS28: EL ROSAL | AV28: RIVERA | AX28: SANTA MARTA | AY28: SAN MARTIN | AZ28: ILES | BA28: PAMPLONA | BF28: EL CARMEN DE CHUCURI | BG28: TOLU VIEJO | BH28: MARIQUITA | BI28: OBANDO
E29: 54. PREPENSIONADO DE ENTIDAD EN LIQUIDACIÓN | I29: EPS MUTUAL SER | J29: COMFAMILIAR HUILA | AD29: SAN_ANDRES | AF29: CARACOLI | AJ29: RIO VIEJO | AK29: COVARACHIA | AL29: VITERBO | AO29: POPAYAN | AQ29: SIPI | AR29: SAN PELAYO | AS29: FACATATIVA | AV29: SALADOBLANCO | AX29: SITIONUEVO | AY29: URIBE | AZ29: IMUES | BA29: PAMPLONITA | BF29: EL GUACAMAYO | BH29: MELGAR | BI29: PALMIRA
E30: 55. AFILIADO PARTICIPE – DEPENDIENTE | I30: EPS SURA (ANTES SUSALUD) | J30: COMFAMILIAR NARIÑO | AD30: SANTANDER | AF30: CARAMANTA | AJ30: SAN CRISTOBAL | AK30: CUBARA | AO30: PUERTO TEJADA | AQ30: TADO | AR30: TIERRALTA | AS30: FOMEQUE | AV30: SAN AGUSTIN | AX30: TENERIFE | AY30: VILLAVICENCIO | AZ30: IPIALES | BA30: PUERTO SANTANDER | BF30: EL PEÑON | BH30: MURILLO | BI30: PRADERA
E31: 57. INDEPENDIENTE VOLUNTARIO AL SISTEMA DE RIESGOS LABORALES | I31: FAMISANAR | J31: COMFAMILIAR PUTUMAYO | AD31: SUCRE | AF31: CAREPA | AJ31: SAN ESTANISLAO | AK31: CUCAITA | AO31: PURACE | AQ31: UNGUIA | AR31: TUCHIN | AS31: FOSCA | AV31: SANTA MARIA | AX31: ZAPAYAN | AY31: VISTAHERMOSA | AZ31: LA CRUZ | BA31: RAGONVALIA | BF31: EL PLAYON | BH31: NATAGAIMA | BI31: RESTREPO
E32: 59. INDEPENDIENTE CON CONTRATO DE PRESTACIÓN DE SERVICIOS SUPERIOR A 1 MES | I32: FONDO DE FERROCARRILES NACIONALES DE COLOMBIA | J32: COMFAMILIAR RISARALDA | AD32: TOLIMA | AF32: CAROLINA | AJ32: SAN FERNANDO | AK32: CUITIVA | AO32: ROSAS | AQ32: UNION PANAMERICANA | AR32: VALENCIA | AS32: FUNZA | AV32: SUAZA | AX32: ZONA BANANERA | AZ32: LA FLORIDA | BA32: SALAZAR | BF32: ENCINO | BH32: ORTEGA | BI32: RIOFRIO
E33: 60. EDIL NO BENEFICIARIO DEL FSP | I33: FOSYGA | J33: COMFANDI | AD33: VALLE | AF33: CAUCASIA | AJ33: SAN JACINTO | AK33: DUITAMA | AO33: SAN SEBASTIAN | AS33: FUQUENE | AV33: TARQUI | AZ33: LA LLANADA | BA33: SAN CALIXTO | BF33: ENCISO | BH33: PALOCABILDO | BI33: ROLDANILLO
E34: 62. PERSONAL DEL MAGISTERIO | I34: FOSYGA RÉGIMEN DE EXCEPCIÓN | J34: COMFANORTE | AD34: VAUPES | AF34: CHIGORODO | AJ34: SAN JACINTO DEL CAUCA | AK34: EL COCUY | AO34: SANTA ROSA | AS34: FUSAGASUGA | AV34: TELLO | AZ34: LA TOLA | BA34: SAN CAYETANO | BF34: FLORIAN | BH34: PIEDRAS | BI34: SAN PEDRO
E35: 65. DEPENDIENTE VINCULADO AL PISO DE PROTECCIÓN SOCIAL | I35: FOSYGA RESIDENTE EXTERIOR O RÉGIMEN SUBSIDIADO | J35: COMFAORIENTE | AD35: VICHADA | AF35: CISNEROS | AJ35: SAN JUAN NEPOMUCENO | AK35: EL ESPINO | AO35: SANTANDER DE QUILICHAO | AS35: GACHALA | AV35: TERUEL | AZ35: LA UNION | BA35: SANTIAGO | BF35: FLORIDABLANCA | BH35: PLANADAS | BI35: SEVILLA
E36: 66. INDEPENDIENTE VINCULADO AL PISO DE PROTECCIÓN SOCIAL | I36: MALLAMAS | J36: COMFASUCRE | AF36: CIUDAD BOLIVAR | AJ36: SAN MARTIN DE LOBA | AK36: FIRAVITOBA | AO36: SILVIA | AS36: GACHANCIPA | AV36: TESALIA | AZ36: LEIVA | BA36: SARDINATA | BF36: GALAN | BH36: PRADO | BI36: TORO
E37: 67. VOLUNTARIO EN PRIMERA RESPUESTA | I37: MEDIMAS EPS | J37: COMFATOLIMA | AF37: COCORNA | AJ37: SAN PABLO | AK37: FLORESTA | AO37: SOTARA | AS37: GACHETA | AV37: TIMANA | AZ37: LINARES | BA37: SILOS | BF37: GAMBITA | BH37: PURIFICACION | BI37: TRUJILLO
E38: 68. DEPENDIENTE VETERANO DE LA FUERZA PÚBLICA | I38: MEDIMAS MOVILIDAD | J38: COMFENALCO ANTIOQUIA | AF38: CONCEPCION | AJ38: SANTA CATALINA | AK38: GACHANTIVA | AO38: SUAREZ | AS38: GAMA | AV38: VILLAVIEJA | AZ38: LOS ANDES | BA38: TEORAMA | BF38: GEPSA | BH38: RIOBLANCO | BI38: TULUA
I39: MUTUAL SER | J39: COMFENALCO CARTAGENA | AF39: CONCORDIA | AJ39: SANTA ROSA | AK39: GAMEZA | AO39: SUCRE | AS39: GIRARDOT | AV39: YAGUARA | AZ39: MAGI | BA39: TIBU | BF39: GIRON | BH39: RONCESVALLES | BI39: ULLOA
I40: NUEVA E.P.S. | J40: COMFENALCO QUINDIO | AF40: COPACABANA | AJ40: SANTA ROSA DEL SUR | AK40: GARAGOA | AO40: TIMBIO | AS40: GRANADA | AZ40: MALLAMA | BA40: TOLEDO | BF40: GUACA | BH40: ROVIRA | BI40: VERSALLES
I41: NUEVA EPS MOVILIDAD | J41: COMFENALCO SANTANDER | AF41: DABEIBA | AJ41: SIMITI | AK41: GICAN | AO41: TIMBIQUI | AS41: GUACHETA | AZ41: MOSQUERA | BA41: VILLA CARO | BF41: GUADALUPE | BH41: SALDAÑA | BI41: VIJES
...

Sheet CauPag
A1: No. | B1: Tipo ID | C1: No ID | D1: APELLIDOS Y NOMBRES | E1: Primer Apellido | F1: Segundo Apellido | G1: Primer Nombre | H1: Segundo Nombre | I1: Departamento | J1: Ciudad | K1: Tipo de Cotizante | L1: Subtipo de Cotizante | M1: Horas Laboradas | N1: Extranjero | O1: Colombiano Temporalmente en el Exterior | P1: Fecha Radicación en el Exterior | Q1: ING | R1: Fecha ING | S1: RET | T1: Fecha RET | U1: TDE | V1: TAE | W1: TDP | X1: TAP | Y1: VSP | Z1: Fecha VSP | AA1: VST | AB1: SLN | AC1: Inicio SLN | AD1: Fin SLN | AE1: IGE | AF1: Inicio IGE | AG1: Fin IGE | AH1: LMA | AI1: Inicio LMA | AJ1: Fin LMA | AK1: VAC-LR | AL1: Inicio VAC-LR | AM1: Fin VAC-LR | AN1: AVP | AO1: VCT | AP1: Inicio VCT | AQ1: Fin VCT | AR1: IRL | AS1: Inicio IRL | AT1: Fin IRL | AU1: Correcciones | AV1: Salario Mensual($) | AW1: Salario Integral | AX1: Salario Variable | AY1: Administradora | AZ1: Días | BA1: IBC | BB1: Tarifa | BC1: Valor Cotización | BD1: Indicador Alto Riesgo | BE1: Cotización Voluntaria Afiliado | BF1: Cotización Voluntaria Empleador | BG1: Fondo Solidaridad Pensional | BH1: Fondo Subsistencia | BI1: Valor no Retenido | BJ1: Total | BK1: AFP Destino | BL1: Administradora | BM1: Días | BN1: IBC | BO1: Tarifa | BP1: Valor Cotización | BQ1: Valor UPC | BR1: N° Autorización Incapacidad EG | BS1: Valor Incapacidad EG | BT1: N° Autorización LMA | BU1: Valor Licencia Maternidad | BV1: EPS Destino | BW1: Administradora | BX1: Días | BY1: IBC | BZ1: Tarifa | CA1: Clase | CB1: Centro de Trabajo | CC1: Actividad Económica | CD1: Valor Cotización | CE1: Días | CF1: Administradora CCF | CG1: IBC CCF | CH1: Tarifa CCF | CI1: Valor Cotización CCF | CJ1: IBC Otros Parafiscales | CK1: Tarifa SENA | CL1: Valor Cotización SENA | CM1: Tarifa ICBF | CN1: Valor Cotización ICBF | CO1: Tarifa ESAP | CP1: Valor Cotización ESAP | CQ1: Tarifa MEN | CR1: Valor Cotización MEN | CS1: Exonerado parafiscales y salud | CT1: Tipo ID | CU1: N° ID
A2: CAUSADO | B2: CC | C2: 1000621869 | D2: MENDEZ ROJAS CARLOS ALBERTO | E2: MENDEZ | F2: ROJAS | G2: CARLOS | H2: ALBERTO | I2: BOGOTA_D.E. | J2: BOGOTA | K2: 1. DEPENDIENTE | L2: NINGUNO | M2: 188 | N2: NO | O2: NO | Q2: NO | S2: NO | U2: NO | V2: NO | W2: NO | X2: NO | Y2: NO | AA2: SI | AB2: NO | AE2: NO | AH2: NO | AK2: NO | AN2: NO | AO2: NO | AR2: 0 | AU2: NO | AV2: 1750905 | AW2: NO | AX2: NO | AY2: PORVENIR | AZ2: 30 | BA2: 2032509 | BB2: 0.16 | BC2: 325300 | BE2: 0 | BF2: 0 | BG2: 0 | BH2: 0 | BI2: 0 | BJ2: 325300 | BK2: NINGUNA | BL2: NUEVA E.P.S. | BM2: 30 | BN2: 2032509 | BO2: 0.04 | BP2: 81400 | BQ2: 0 | BS2: 0 | BU2: 0 | BV2: NINGUNA | BW2: COLMENA | BX2: 30 | BY2: 2032509 | BZ2: 0.0696 | CA2: 5 | CB2: CENTRO TRABAJO 24 | CC2: 5711001 | CD2: 141500 | CE2: 30 | CF2: COMPENSAR | CG2: 2032509 | CH2: 0.04 | CI2: 81400 | CJ2: 2032509 | CK2: 0 | CL2: 0 | CM2: 0 | CN2: 0 | CO2: 0 | CP2: 0 | CQ2: 0 | CR2: 0 | CS2: SI
A3: CAUSADO | B3: CC | C3: 1000790715 | D3: MOSQUERA MOSQUERA BRAYAN STIVEN | E3: MOSQUERA | F3: MOSQUERA | G3: BRAYAN | H3: STIVEN | I3: BOGOTA_D.E. | J3: BOGOTA | K3: 1. DEPENDIENTE | L3: NINGUNO | M3: 9 | N3: NO | O3: NO | Q3: Todos los sistemas (ARL, AFP, CCF, EPS) | R3: 46080 | S3: NO | U3: NO | V3: NO | W3: NO | X3: NO | Y3: NO | AA3: NO | AB3: NO | AE3: NO | AH3: NO | AK3: NO | AN3: NO | AO3: NO | AR3: 0 | AU3: NO | AV3: 1750905 | AW3: NO | AX3: NO | AY3: PORVENIR | AZ3: 4 | BA3: 233454 | BB3: 0.16 | BC3: 37400 | BE3: 0 | BF3: 0 | BG3: 0 | BH3: 0 | BI3: 0 | BJ3: 37400 | BK3: NINGUNA | BL3: ALIANSALUD EPS (ANTES COLMEDICA) | BM3: 4 | BN3: 233454 | BO3: 0.04 | BP3: 9400 | BQ3: 0 | BS3: 0 | BU3: 0 | BV3: NINGUNA | BW3: COLMENA | BX3: 4 | BY3: 233454 | BZ3: 0.0696 | CA3: 5 | CB3: CENTRO TRABAJO 24 | CC3: 5711001 | CD3: 16300 | CE3: 4 | CF3: COMPENSAR | CG3: 233454 | CH3: 0.04 | CI3: 9400 | CJ3: 233454 | CK3: 0 | CL3: 0 | CM3: 0 | CN3: 0 | CO3: 0 | CP3: 0 | CQ3: 0 | CR3: 0 | CS3: SI
A4: CAUSADO | B4: CC | C4: 1001798417 | D4: RUA MANGA CARLOS MARIO | E4: RUA | F4: MANGA | G4: CARLOS | H4: MARIO | I4: LA_GUAJIRA | J4: RIOHACHA | K4: 1. DEPENDIENTE | L4: NINGUNO | M4: 204 | N4: NO | O4: NO | Q4: NO | S4: NO | U4: NO | V4: NO | W4: NO | X4: NO | Y4: NO | AA4: SI | AB4: NO | AE4: NO | AH4: NO | AK4: NO | AN4: NO | AO4: NO | AR4: 0 | AU4: NO | AV4: 1889179 | AW4: NO | AX4: NO | AY4: PORVENIR | AZ4: 30 | BA4: 2222363 | BB4: 0.16 | BC4: 355600 | BE4: 0 | BF4: 0 | BG4: 0 | BH4: 0 | BI4: 0 | BJ4: 355600 | BK4: NINGUNA | BL4: SANITAS | BM4: 30 | BN4: 2222363 | BO4: 0.04 | BP4: 88900 | BQ4: 0 | BS4: 0 | BU4: 0 | BV4: NINGUNA | BW4: COLMENA | BX4: 30 | BY4: 2222363 | BZ4: 0.0696 | CA4: 5 | CB4: CENTRO TRABAJO 30 | CC4: 5711001 | CD4: 154700 | CE4: 30 | CF4: COMFAMILIAR GUAJIRA | CG4: 2222363 | CH4: 0.04 | CI4: 88900 | CJ4: 2222363 | CK4: 0 | CL4: 0 | CM4: 0 | CN4: 0 | CO4: 0 | CP4: 0 | CQ4: 0 | CR4: 0 | CS4: SI
A5: CAUSADO | B5: CC | C5: 1001836532 | D5: SANTANA VIDES OSCAR JUNIOR | E5: SANTANA | F5: VIDES | G5: OSCAR | H5: JUNIOR | I5: BOLIVAR | J5: CARTAGENA | K5: 1. DEPENDIENTE | L5: NINGUNO | M5: 201 | N5: NO | O5: NO | Q5: NO | S5: NO | U5: NO | V5: NO | W5: NO | X5: NO | Y5: NO | AA5: SI | AB5: NO | AE5: NO | AH5: NO | AK5: NO | AN5: NO | AO5: NO | AR5: 0 | AU5: NO | AV5: 2308750 | AW5: NO | AX5: NO | AY5: PORVENIR | AZ5: 30 | BA5: 2643077 | BB5: 0.16 | BC5: 422900 | BE5: 0 | BF5: 0 | BG5: 0 | BH5: 0 | BI5: 0 | BJ5: 422900 | BK5: NINGUNA | BL5: NUEVA E.P.S. | BM5: 30 | BN5: 2643077 | BO5: 0.04 | BP5: 105800 | BQ5: 0 | BS5: 0 | BU5: 0 | BV5: NINGUNA | BW5: COLMENA | BX5: 30 | BY5: 2643077 | BZ5: 0.0696 | CA5: 5 | CB5: CENTRO TRABAJO 8 | CC5: 5711001 | CD5: 184000 | CE5: 30 | CF5: COMFENALCO CARTAGENA | CG5: 2584226 | CH5: 0.04 | CI5: 103400 | CJ5: 2584226 | CK5: 0 | CL5: 0 | CM5: 0 | CN5: 0 | CO5: 0 | CP5: 0 | CQ5: 0 | CR5: 0 | CS5: SI
A6: CAUSADO | B6: CC | C6: 1002143370 | D6: CANTILLO PERTUZ GIANTKHRLOOS G. | E6: CANTILLO | F6: PERTUZ | G6: GIANTKHRLOOS | H6: G. | I6: BOGOTA_D.E. | J6: BOGOTA | K6: 1. DEPENDIENTE | L6: NINGUNO | M6: 0 | N6: NO | O6: NO | Q6: NO | S6: NO | U6: NO | V6: NO | W6: NO | X6: NO | Y6: NO | AA6: NO | AB6: NO | AE6: NO | AH6: NO | AK6: LICENCIA REMUNERADA | AL6: 46069 | AM6: 46069 | AN6: NO | AO6: NO | AR6: 0 | AU6: NO | AV6: 1750905 | AW6: NO | AX6: NO | AY6: PORVENIR | AZ6: 1 | BA6: 58364 | BB6: 0.16 | BC6: 9400 | BE6: 0 | BF6: 0 | BG6: 0 | BH6: 0 | BI6: 0 | BJ6: 9400 | BK6: NINGUNA | BL6: SANITAS | BM6: 1 | BN6: 58364 | BO6: 0.04 | BP6: 2400 | BQ6: 0 | BS6: 0 | BU6: 0 | BV6: NINGUNA | BW6: COLMENA | BX6: 1 | BY6: 58364 | BZ6: 0 | CA6: 5 | CB6: CENTRO TRABAJO 24 | CC6: 5711001 | CD6: 0 | CE6: 1 | CF6: COMPENSAR | CG6: 58364 | CH6: 0.04 | CI6: 2400 | CJ6: 58364 | CK6: 0 | CL6: 0 | CM6: 0 | CN6: 0 | CO6: 0 | CP6: 0 | CQ6: 0 | CR6: 0 | CS6: SI
A7: CAUSADO | B7: CC | C7: 1002143370 | D7: CANTILLO PERTUZ GIANTKHRLOOS G. | E7: CANTILLO | F7: PERTUZ | G7: GIANTKHRLOOS | H7: G. | I7: BOGOTA_D.E. | J7: BOGOTA | K7: 1. DEPENDIENTE | L7: NINGUNO | M7: 188 | N7: NO | O7: NO | Q7: NO | S7: NO | U7: NO | V7: NO | W7: NO | X7: NO | Y7: NO | AA7: SI | AB7: NO | AE7: NO | AH7: NO | AK7: NO | AN7: NO | AO7: NO | AR7: 0 | AU7: NO | AV7: 1750905 | AW7: NO | AX7: NO | AY7: PORVENIR | AZ7: 29 | BA7: 2073895 | BB7: 0.16 | BC7: 331900 | BE7: 0 | BF7: 0 | BG7: 0 | BH7: 0 | BI7: 0 | BJ7: 331900 | BK7: NINGUNA | BL7: SANITAS | BM7: 29 | BN7: 2073895 | BO7: 0.04 | BP7: 83000 | BQ7: 0 | BS7: 0 | BU7: 0 | BV7: NINGUNA | BW7: COLMENA | BX7: 29 | BY7: 2073895 | BZ7: 0.0696 | CA7: 5 | CB7: CENTRO TRABAJO 24 | CC7: 5711001 | CD7: 144400 | CE7: 29 | CF7: COMPENSAR | CG7: 2073895 | CH7: 0.04 | CI7: 83000 | CJ7: 2073895 | CK7: 0 | CL7: 0 | CM7: 0 | CN7: 0 | CO7: 0 | CP7: 0 | CQ7: 0 | CR7: 0 | CS7: SI
A8: CAUSADO | B8: CC | C8: 1002487151 | D8: ZABALETA SALCEDO NEL ENRIQUE | E8: ZABALETA | F8: SALCEDO | G8: NEL | H8: ENRIQUE | I8: BOGOTA_D.E. | J8: BOGOTA | K8: 1. DEPENDIENTE | L8: NINGUNO | M8: 0 | N8: NO | O8: NO | Q8: NO | S8: NO | U8: NO | V8: NO | W8: NO | X8: NO | Y8: NO | AA8: NO | AB8: LICENCIA NO REMUNERADA | AC8: 46054 | AD8: 46055 | AE8: NO | AH8: NO | AK8: NO | AN8: NO | AO8: NO | AR8: 0 | AU8: NO | AV8: 1750905 | AW8: NO | AX8: NO | AY8: PORVENIR | AZ8: 2 | BA8: 116727 | BB8: 0.16 | BC8: 18700 | BE8: 0 | BF8: 0 | BG8: 0 | BH8: 0 | BI8: 0 | BJ8: 18700 | BK8: NINGUNA | BL8: SALUD TOTAL | BM8: 2 | BN8: 116727 | BO8: 0 | BP8: 0 | BQ8: 0 | BS8: 0 | BU8: 0 | BV8: NINGUNA | BW8: COLMENA | BX8: 2 | BY8: 116727 | BZ8: 0 | CA8: 5 | CB8: CENTRO TRABAJO 24 | CC8: 5711001 | CD8: 0 | CE8: 2 | CF8: COMPENSAR | CG8: 0 | CH8: 0 | CI8: 0 | CJ8: 0 | CK8: 0 | CL8: 0 | CM8: 0 | CN8: 0 | CO8: 0 | CP8: 0 | CQ8: 0 | CR8: 0 | CS8: SI
A9: CAUSADO | B9: CC | C9: 1002487151 | D9: ZABALETA SALCEDO NEL ENRIQUE | E9: ZABALETA | F9: SALCEDO | G9: NEL | H9: ENRIQUE | I9: BOGOTA_D.E. | J9: BOGOTA | K9: 1. DEPENDIENTE | L9: NINGUNO | M9: 0 | N9: NO | O9: NO | Q9: NO | S9: NO | U9: NO | V9: NO | W9: NO | X9: NO | Y9: NO | AA9: NO | AB9: LICENCIA NO REMUNERADA | AC9: 46055 | AD9: 46061 | AE9: NO | AH9: NO | AK9: NO | AN9: NO | AO9: NO | AR9: 0 | AU9: NO | AV9: 1750905 | AW9: NO | AX9: NO | AY9: PORVENIR | AZ9: 7 | BA9: 408545 | BB9: 0.16 | BC9: 65400 | BE9: 0 | BF9: 0 | BG9: 0 | BH9: 0 | BI9: 0 | BJ9: 65400 | BK9: NINGUNA | BL9: SALUD TOTAL | BM9: 7 | BN9: 408545 | BO9: 0 | BP9: 0 | BQ9: 0 | BS9: 0 | BU9: 0 | BV9: NINGUNA | BW9: COLMENA | BX9: 7 | BY9: 408545 | BZ9: 0 | CA9: 5 | CB9: CENTRO TRABAJO 24 | CC9: 5711001 | CD9: 0 | CE9: 7 | CF9: COMPENSAR | CG9: 0 | CH9: 0 | CI9: 0 | CJ9: 0 | CK9: 0 | CL9: 0 | CM9: 0 | CN9: 0 | CO9: 0 | CP9: 0 | CQ9: 0 | CR9: 0 | CS9: SI
A10: CAUSADO | B10: CC | C10: 1002487151 | D10: ZABALETA SALCEDO NEL ENRIQUE | E10: ZABALETA | F10: SALCEDO | G10: NEL | H10: ENRIQUE | I10: BOGOTA_D.E. | J10: BOGOTA | K10: 1. DEPENDIENTE | L10: NINGUNO | M10: 140 | N10: NO | O10: NO | Q10: NO | S10: NO | U10: NO | V10: NO | W10: NO | X10: NO | Y10: NO | AA10: SI | AB10: NO | AE10: NO | AH10: NO | AK10: NO | AN10: NO | AO10: NO | AR10: 0 | AU10: NO | AV10: 1750905 | AW10: NO | AX10: NO | AY10: PORVENIR | AZ10: 21 | BA10: 1545572 | BB10: 0.16 | BC10: 247300 | BE10: 0 | BF10: 0 | BG10: 0 | BH10: 0 | BI10: 0 | BJ10: 247300 | BK10: NINGUNA | BL10: SALUD TOTAL | BM10: 21 | BN10: 1545572 | BO10: 0.04 | BP10: 61900 | BQ10: 0 | BS10: 0 | BU10: 0 | BV10: NINGUNA | BW10: COLMENA | BX10: 21 | BY10: 1545572 | BZ10: 0.0696 | CA10: 5 | CB10: CENTRO TRABAJO 24 | CC10: 5711001 | CD10: 107600 | CE10: 21 | CF10: COMPENSAR | CG10: 1545572 | CH10: 0.04 | CI10: 61900 | CJ10: 1545572 | CK10: 0 | CL10: 0 | CM10: 0 | CN10: 0 | CO10: 0 | CP10: 0 | CQ10: 0 | CR10: 0 | CS10: SI
A11: CAUSADO | B11: CC | C11: 1002559775 | D11: SANCHEZ VARGAS OMAR ALEJANDRO | E11: SANCHEZ | F11: VARGAS | G11: OMAR | H11: ALEJANDRO | I11: BOGOTA_D.E. | J11: BOGOTA | K11: 1. DEPENDIENTE | L11: NINGUNO | M11: 162 | N11: NO | O11: NO | Q11: Todos los sistemas (ARL, AFP, CCF, EPS) | R11: 46059 | S11: NO | U11: NO | V11: NO | W11: NO | X11: NO | Y11: NO | AA11: SI | AB11: NO | AE11: NO | AH11: NO | AK11: NO | AN11: NO | AO11: NO | AR11: 0 | AU11: NO | AV11: 2223339 | AW11: NO | AX11: NO | AY11: PORVENIR | AZ11: 25 | BA11: 2334844 | BB11: 0.16 | BC11: 373600 | BE11: 0 | BF11: 0 | BG11: 0 | BH11: 0 | BI11: 0 | BJ11: 373600 | BK11: NINGUNA | BL11: NUEVA E.P.S. | BM11: 25 | BN11: 2334844 | BO11: 0.04 | BP11: 93400 | BQ11: 0 | BS11: 0 | BU11: 0 | BV11: NINGUNA | BW11: COLMENA | BX11: 25 | BY11: 2334844 | BZ11: 0.0696 | CA11: 5 | CB11: CENTRO TRABAJO 24 | CC11: 5711001 | CD11: 162600 | CE11: 25 | CF11: COMPENSAR | CG11: 2334844 | CH11: 0.04 | CI11: 93400 | CJ11: 2334844 | CK11: 0 | CL11: 0 | CM11: 0 | CN11: 0 | CO11: 0 | CP11: 0 | CQ11: 0 | CR11: 0 | CS11: SI
A12: CAUSADO | B12: CC | C12: 1003252787 | D12: MANGA FRIA JUAN LUIS | E12: MANGA | F12: FRIA | G12: JUAN | H12: LUIS | I12: LA_GUAJIRA | J12: RIOHACHA | K12: 1. DEPENDIENTE | L12: NINGUNO | M12: 0 | N12: NO | O12: NO | Q12: NO | S12: NO | U12: NO | V12: NO | W12: NO | X12: NO | Y12: NO | AA12: NO | AB12: LICENCIA NO REMUNERADA | AC12: 46054 | AD12: 46054 | AE12: NO | AH12: NO | AK12: NO | AN12: NO | AO12: NO | AR12: 0 | AU12: NO | AV12: 1750905 | AW12: NO | AX12: NO | AY12: PORVENIR | AZ12: 1 | BA12: 58364 | BB12: 0.16 | BC12: 9400 | BE12: 0 | BF12: 0 | BG12: 0 | BH12: 0 | BI12: 0 | BJ12: 9400 | BK12: NINGUNA | BL12: COOSALUD MOVILIDAD | BM12: 1 | BN12: 58364 | BO12: 0 | BP12: 0 | BQ12: 0 | BS12: 0 | BU12: 0 | BV12: NINGUNA | BW12: COLMENA | BX12: 1 | BY12: 58364 | BZ12: 0 | CA12: 5 | CB12: CENTRO TRABAJO 30 | CC12: 5711001 | CD12: 0 | CE12: 1 | CF12: COMFAMILIAR GUAJIRA | CG12: 0 | CH12: 0 | CI12: 0 | CJ12: 0 | CK12: 0 | CL12: 0 | CM12: 0 | CN12: 0 | CO12: 0 | CP12: 0 | CQ12: 0 | CR12: 0 | CS12: SI
A13: CAUSADO | B13: CC | C13: 1003252787 | D13: MANGA FRIA JUAN LUIS | E13: MANGA | F13: FRIA | G13: JUAN | H13: LUIS | I13: LA_GUAJIRA | J13: RIOHACHA | K13: 1. DEPENDIENTE | L13: NINGUNO | M13: 0 | N13: NO | O13: NO | Q13: NO | S13: NO | U13: NO | V13: NO | W13: NO | X13: NO | Y13: NO | AA13: NO | AB13: LICENCIA NO REMUNERADA | AC13: 46069 | AD13: 46069 | AE13: NO | AH13: NO | AK13: NO | AN13: NO | AO13: NO | AR13: 0 | AU13: NO | AV13: 1750905 | AW13: NO | AX13: NO | AY13: PORVENIR | AZ13: 1 | BA13: 58364 | BB13: 0.16 | BC13: 9400 | BE13: 0 | BF13: 0 | BG13: 0 | BH13: 0 | BI13: 0 | BJ13: 9400 | BK13: NINGUNA | BL13: COOSALUD MOVILIDAD | BM13: 1 | BN13: 58364 | BO13: 0 | BP13: 0 | BQ13: 0 | BS13: 0 | BU13: 0 | BV13: NINGUNA | BW13: COLMENA | BX13: 1 | BY13: 58364 | BZ13: 0 | CA13: 5 | CB13: CENTRO TRABAJO 30 | CC13: 5711001 | CD13: 0 | CE13: 1 | CF13: COMFAMILIAR GUAJIRA | CG13: 0 | CH13: 0 | CI13: 0 | CJ13: 0 | CK13: 0 | CL13: 0 | CM13: 0 | CN13: 0 | CO13: 0 | CP13: 0 | CQ13: 0 | CR13: 0 | CS13: SI
A14: CAUSADO | B14: CC | C14: 1003252787 | D14: MANGA FRIA JUAN LUIS | E14: MANGA | F14: FRIA | G14: JUAN | H14: LUIS | I14: LA_GUAJIRA | J14: RIOHACHA | K14: 1. DEPENDIENTE | L14: NINGUNO | M14: 198 | N14: NO | O14: NO | Q14: NO | S14: NO | U14: NO | V14: NO | W14: NO | X14: NO | Y14: NO | AA14: SI | AB14: NO | AE14: NO | AH14: NO | AK14: NO | AN14: NO | AO14: NO | AR14: 0 | AU14: NO | AV14: 1750905 | AW14: NO | AX14: NO | AY14: PORVENIR | AZ14: 28 | BA14: 1972818 | BB14: 0.16 | BC14: 315700 | BE14: 0 | BF14: 0 | BG14: 0 | BH14: 0 | BI14: 0 | BJ14: 315700 | BK14: NINGUNA | BL14: COOSALUD MOVILIDAD | BM14: 28 | BN14: 1972818 | BO14: 0.04 | BP14: 79000 | BQ14: 0 | BS14: 0 | BU14: 0 | BV14: NINGUNA | BW14: COLMENA | BX14: 28 | BY14: 1972818 | BZ14: 0.0696 | CA14: 5 | CB14: CENTRO TRABAJO 30 | CC14: 5711001 | CD14: 137400 | CE14: 28 | CF14: COMFAMILIAR GUAJIRA | CG14: 1972819 | CH14: 0.04 | CI14: 79000 | CJ14: 1972819 | CK14: 0 | CL14: 0 | CM14: 0 | CN14: 0 | CO14: 0 | CP14: 0 | CQ14: 0 | CR14: 0 | CS14: SI
A15: CAUSADO | B15: CC | C15: 1003557217 | D15: OSORIO HERNANDEZ KEVIN ALBERTO | E15: OSORIO | F15: HERNANDEZ | G15: KEVIN | H15: ALBERTO | I15: BOGOTA_D.E. | J15: BOGOTA | K15: 1. DEPENDIENTE | L15: NINGUNO | M15: 0 | N15: NO | O15: NO | Q15: Todos los sistemas (ARL, AFP, CCF, EPS) | R15: 46081 | S15: NO | U15: NO | V15: NO | W15: NO | X15: NO | Y15: NO | AA15: NO | AB15: NO | AE15: NO | AH15: NO | AK15: NO | AN15: NO | AO15: NO | AR15: 0 | AU15: NO | AV15: 1785595 | AW15: NO | AX15: NO | AY15: COLPENSIONES | AZ15: 3 | BA15: 178560 | BB15: 0.16 | BC15: 28600 | BE15: 0 | BF15: 0 | BG15: 0 | BH15: 0 | BI15: 0 | BJ15: 28600 | BK15: NINGUNA | BL15: FONDO DE FERROCARRILES NACIONALES DE COLOMBIA | BM15: 3 | BN15: 178560 | BO15: 0.04 | BP15: 7200 | BQ15: 0 | BS15: 0 | BU15: 0 | BV15: NINGUNA | BW15: COLMENA | BX15: 3 | BY15: 178560 | BZ15: 0.0696 | CA15: 5 | CB15: CENTRO TRABAJO 24 | CC15: 5711001 | CD15: 12500 | CE15: 3 | CF15: COMPENSAR | CG15: 178560 | CH15: 0.04 | CI15: 7200 | CJ15: 178560 | CK15: 0 | CL15: 0 | CM15: 0 | CN15: 0 | CO15: 0 | CP15: 0 | CQ15: 0 | CR15: 0 | CS15: SI
A16: CAUSADO | B16: CC | C16: 1003736605 | D16: ALVAREZ CORREA JOSE ANGEL | E16: ALVAREZ | F16: CORREA | G16: JOSE | H16: ANGEL | I16: LA_GUAJIRA | J16: RIOHACHA | K16: 1. DEPENDIENTE | L16: NINGUNO | M16: 0 | N16: NO | O16: NO | Q16: NO | S16: NO | U16: NO | V16: NO | W16: NO | X16: NO | Y16: NO | AA16: NO | AB16: LICENCIA NO REMUNERADA | AC16: 46054 | AD16: 46054 | AE16: NO | AH16: NO | AK16: NO | AN16: NO | AO16: NO | AR16: 0 | AU16: NO | AV16: 1785595 | AW16: NO | AX16: NO | AY16: PORVENIR | AZ16: 1 | BA16: 59520 | BB16: 0.16 | BC16: 9600 | BE16: 0 | BF16: 0 | BG16: 0 | BH16: 0 | BI16: 0 | BJ16: 9600 | BK16: NINGUNA | BL16: CAJACOPI | BM16: 1 | BN16: 59520 | BO16: 0 | BP16: 0 | BQ16: 0 | BS16: 0 | BU16: 0 | BV16: NINGUNA | BW16: COLMENA | BX16: 1 | BY16: 59520 | BZ16: 0 | CA16: 5 | CB16: CENTRO TRABAJO 30 | CC16: 5711001 | CD16: 0 | CE16: 1 | CF16: COMFAMILIAR GUAJIRA | CG16: 0 | CH16: 0 | CI16: 0 | CJ16: 0 | CK16: 0 | CL16: 0 | CM16: 0 | CN16: 0 | CO16: 0 | CP16: 0 | CQ16: 0 | CR16: 0 | CS16: SI
A17: CAUSADO | B17: CC | C17: 1003736605 | D17: ALVAREZ CORREA JOSE ANGEL | E17: ALVAREZ | F17: CORREA | G17: JOSE | H17: ANGEL | I17: LA_GUAJIRA | J17: RIOHACHA | K17: 1. DEPENDIENTE | L17: NINGUNO | M17: 0 | N17: NO | O17: NO | Q17: NO | S17: NO | U17: NO | V17: NO | W17: NO | X17: NO | Y17: NO | AA17: NO | AB17: NO | AE17: INCAPACIDAD GENERAL | AF17: 46056 | AG17: 46056 | AH17: NO | AK17: NO | AN17: NO | AO17: NO | AR17: 0 | AU17: NO | AV17: 1785595 | AW17: NO | AX17: NO | AY17: PORVENIR | AZ17: 1 | BA17: 69937 | BB17: 0.16 | BC17: 11200 | BE17: 0 | BF17: 0 | BG17: 0 | BH17: 0 | BI17: 0 | BJ17: 11200 | BK17: NINGUNA | BL17: CAJACOPI | BM17: 1 | BN17: 69937 | BO17: 0.04 | BP17: 2800 | BQ17: 0 | BS17: 0 | BU17: 0 | BV17: NINGUNA | BW17: COLMENA | BX17: 1 | BY17: 69937 | BZ17: 0 | CA17: 5 | CB17: CENTRO TRABAJO 30 | CC17: 5711001 | CD17: 0 | CE17: 1 | CF17: COMFAMILIAR GUAJIRA | CG17: 0 | CH17: 0 | CI17: 0 | CJ17: 0 | CK17: 0 | CL17: 0 | CM17: 0 | CN17: 0 | CO17: 0 | CP17: 0 | CQ17: 0 | CR17: 0 | CS17: SI
A18: CAUSADO | B18: CC | C18: 1003736605 | D18: ALVAREZ CORREA JOSE ANGEL | E18: ALVAREZ | F18: CORREA | G18: JOSE | H18: ANGEL | I18: LA_GUAJIRA | J18: RIOHACHA | K18: 1. DEPENDIENTE | L18: NINGUNO | M18: 192 | N18: NO | O18: NO | Q18: NO | S18: Todos los sistemas (ARL, AFP, CCF, EPS) | T18: 46079 | U18: NO | V18: NO | W18: NO | X18: NO | Y18: NO | AA18: SI | AB18: NO | AE18: NO | AH18: NO | AK18: NO | AN18: NO | AO18: NO | AR18: 0 | AU18: NO | AV18: 1785595 | AW18: NO | AX18: NO | AY18: PORVENIR | AZ18: 24 | BA18: 2913713 | BB18: 0.16 | BC18: 466200 | BE18: 0 | BF18: 0 | BG18: 0 | BH18: 0 | BI18: 0 | BJ18: 466200 | BK18: NINGUNA | BL18: CAJACOPI | BM18: 24 | BN18: 2913713 | BO18: 0.04 | BP18: 116600 | BQ18: 0 | BS18: 0 | BU18: 0 | BV18: NINGUNA | BW18: COLMENA | BX18: 24 | BY18: 2913713 | BZ18: 0.0696 | CA18: 5 | CB18: CENTRO TRABAJO 30 | CC18: 5711001 | CD18: 202800 | CE18: 24 | CF18: COMFAMILIAR GUAJIRA | CG18: 4259565 | CH18: 0.04 | CI18: 170400 | CJ18: 4259565 | CK18: 0 | CL18: 0 | CM18: 0 | CN18: 0 | CO18: 0 | CP18: 0 | CQ18: 0 | CR18: 0 | CS18: SI
A19: CAUSADO | B19: CC | C19: 1003903787 | D19: MALDONADO LOSADA EDINSON ANDRES | E19: MALDONADO | F19: LOSADA | G19: EDINSON | H19: ANDRES | I19: BOGOTA_D.E. | J19: BOGOTA | K19: 1. DEPENDIENTE | L19: NINGUNO | M19: 0 | N19: NO | O19: NO | Q19: NO | S19: NO | U19: NO | V19: NO | W19: NO | X19: NO | Y19: NO | AA19: NO | AB19: NO | AE19: NO | AH19: NO | AK19: LICENCIA REMUNERADA | AL19: 46054 | AM19: 46054 | AN19: NO | AO19: NO | AR19: 0 | AU19: NO | AV19: 1750905 | AW19: NO | AX19: NO | AY19: PORVENIR | AZ19: 1 | BA19: 58364 | BB19: 0.16 | BC19: 9400 | BE19: 0 | BF19: 0 | BG19: 0 | BH19: 0 | BI19: 0 | BJ19: 9400 | BK19: NINGUNA | BL19: SALUD TOTAL | BM19: 1 | BN19: 58364 | BO19: 0.04 | BP19: 2400 | BQ19: 0 | BS19: 0 | BU19: 0 | BV19: NINGUNA | BW19: COLMENA | BX19: 1 | BY19: 58364 | BZ19: 0 | CA19: 5 | CB19: CENTRO TRABAJO 24 | CC19: 5711001 | CD19: 0 | CE19: 1 | CF19: COMPENSAR | CG19: 58364 | CH19: 0.04 | CI19: 2400 | CJ19: 58364 | CK19: 0 | CL19: 0 | CM19: 0 | CN19: 0 | CO19: 0 | CP19: 0 | CQ19: 0 | CR19: 0 | CS19: SI
A20: CAUSADO | B20: CC | C20: 1003903787 | D20: MALDONADO LOSADA EDINSON ANDRES | E20: MALDONADO | F20: LOSADA | G20: EDINSON | H20: ANDRES | I20: BOGOTA_D.E. | J20: BOGOTA | K20: 1. DEPENDIENTE | L20: NINGUNO | M20: 0 | N20: NO | O20: NO | Q20: NO | S20: NO | U20: NO | V20: NO | W20: NO | X20: NO | Y20: NO | AA20: NO | AB20: NO | AE20: INCAPACIDAD GENERAL | AF20: 46062 | AG20: 46063 | AH20: NO | AK20: NO | AN20: NO | AO20: NO | AR20: 0 | AU20: NO | AV20: 1750905 | AW20: NO | AX20: NO | AY20: PORVENIR | AZ20: 2 | BA20: 205820 | BB20: 0.16 | BC20: 33000 | BE20: 0 | BF20: 0 | BG20: 0 | BH20: 0 | BI20: 0 | BJ20: 33000 | BK20: NINGUNA | BL20: SALUD TOTAL | BM20: 2 | BN20: 205820 | BO20: 0.04 | BP20: 8300 | BQ20: 0 | BS20: 0 | BU20: 0 | BV20: NINGUNA | BW20: COLMENA | BX20: 2 | BY20: 205820 | BZ20: 0 | CA20: 5 | CB20: CENTRO TRABAJO 24 | CC20: 5711001 | CD20: 0 | CE20: 2 | CF20: COMPENSAR | CG20: 0 | CH20: 0 | CI20: 0 | CJ20: 0 | CK20: 0 | CL20: 0 | CM20: 0 | CN20: 0 | CO20: 0 | CP20: 0 | CQ20: 0 | CR20: 0 | CS20: SI
A21: CAUSADO | B21: CC | C21: 1003903787 | D21: MALDONADO LOSADA EDINSON ANDRES | E21: MALDONADO | F21: LOSADA | G21: EDINSON | H21: ANDRES | I21: BOGOTA_D.E. | J21: BOGOTA | K21: 1. DEPENDIENTE | L21: NINGUNO | M21: 0 | N21: NO | O21: NO | Q21: NO | S21: NO | U21: NO | V21: NO | W21: NO | X21: NO | Y21: NO | AA21: NO | AB21: LICENCIA NO REMUNERADA | AC21: 46069 | AD21: 46070 | AE21: NO | AH21: NO | AK21: NO | AN21: NO | AO21: NO | AR21: 0 | AU21: NO | AV21: 1750905 | AW21: NO | AX21: NO | AY21: PORVENIR | AZ21: 2 | BA21: 116727 | BB21: 0.16 | BC21: 18700 | BE21: 0 | BF21: 0 | BG21: 0 | BH21: 0 | BI21: 0 | BJ21: 18700 | BK21: NINGUNA | BL21: SALUD TOTAL | BM21: 2 | BN21: 116727 | BO21: 0 | BP21: 0 | BQ21: 0 | BS21: 0 | BU21: 0 | BV21: NINGUNA | BW21: COLMENA | BX21: 2 | BY21: 116727 | BZ21: 0 | CA21: 5 | CB21: CENTRO TRABAJO 24 | CC21: 5711001 | CD21: 0 | CE21: 2 | CF21: COMPENSAR | CG21: 0 | CH21: 0 | CI21: 0 | CJ21: 0 | CK21: 0 | CL21: 0 | CM21: 0 | CN21: 0 | CO21: 0 | CP21: 0 | CQ21: 0 | CR21: 0 | CS21: SI
A22: CAUSADO | B22: CC | C22: 1003903787 | D22: MALDONADO LOSADA EDINSON ANDRES | E22: MALDONADO | F22: LOSADA | G22: EDINSON | H22: ANDRES | I22: BOGOTA_D.E. | J22: BOGOTA | K22: 1. DEPENDIENTE | L22: NINGUNO | M22: 124 | N22: NO | O22: NO | Q22: NO | S22: Todos los sistemas (ARL, AFP, CCF, EPS) | T22: 46074 | U22: NO | V22: NO | W22: NO | X22: NO | Y22: NO | AA22: SI | AB22: NO | AE22: NO | AH22: NO | AK22: NO | AN22: NO | AO22: NO | AR22: 0 | AU22: NO | AV22: 1750905 | AW22: NO | AX22: NO | AY22: PORVENIR | AZ22: 16 | BA22: 1600632 | BB22: 0.16 | BC22: 256200 | BE22: 0 | BF22: 0 | BG22: 0 | BH22: 0 | BI22: 0 | BJ22: 256200 | BK22: NINGUNA | BL22: SALUD TOTAL | BM22: 16 | BN22: 1600632 | BO22: 0.04 | BP22: 64100 | BQ22: 0 | BS22: 0 | BU22: 0 | BV22: NINGUNA | BW22: COLMENA | BX22: 16 | BY22: 1600632 | BZ22: 0.0696 | CA22: 5 | CB22: CENTRO TRABAJO 24 | CC22: 5711001 | CD22: 111500 | CE22: 16 | CF22: COMPENSAR | CG22: 2098116 | CH22: 0.04 | CI22: 84000 | CJ22: 2098116 | CK22: 0 | CL22: 0 | CM22: 0 | CN22: 0 | CO22: 0 | CP22: 0 | CQ22: 0 | CR22: 0 | CS22: SI
A23: CAUSADO | B23: CC | C23: 1004271898 | D23: DE AVILA ARRIETA BRAYAN RAFAEL | E23: DE AVILA | F23: ARRIETA | G23: BRAYAN | H23: RAFAEL | I23: BOGOTA_D.E. | J23: BOGOTA | K23: 1. DEPENDIENTE | L23: NINGUNO | M23: 24 | N23: NO | O23: NO | Q23: NO | S23: Todos los sistemas (ARL, AFP, CCF, EPS) | T23: 46055 | U23: NO | V23: NO | W23: NO | X23: NO | Y23: NO | AA23: SI | AB23: NO | AE23: NO | AH23: NO | AK23: NO | AN23: NO | AO23: NO | AR23: 0 | AU23: NO | AV23: 2223339 | AW23: NO | AX23: NO | AY23: PORVENIR | AZ23: 2 | BA23: 980747 | BB23: 0.16 | BC23: 157000 | BE23: 0 | BF23: 0 | BG23: 0 | BH23: 0 | BI23: 0 | BJ23: 157000 | BK23: NINGUNA | BL23: SALUD TOTAL | BM23: 2 | BN23: 980747 | BO23: 0.125 | BP23: 122600 | BQ23: 0 | BS23: 0 | BU23: 0 | BV23: NINGUNA | BW23: COLMENA | BX23: 2 | BY23: 980747 | BZ23: 0.0696 | CA23: 5 | CB23: CENTRO TRABAJO 24 | CC23: 5711001 | CD23: 68300 | CE23: 2 | CF23: COMPENSAR | CG23: 1535765 | CH23: 0.04 | CI23: 61500 | CJ23: 1535765 | CK23: 0.02 | CL23: 30800 | CM23: 0.03 | CN23: 46100 | CO23: 0 | CP23: 0 | CQ23: 0 | CR23: 0 | CS23: SI
A24: CAUSADO | B24: CC | C24: 1004308195 | D24: RODRIGUEZ CONTRERAS BLADIMIR JOSE | E24: RODRIGUEZ | F24: CONTRERAS | G24: BLADIMIR | H24: JOSE | I24: LA_GUAJIRA | J24: RIOHACHA | K24: 1. DEPENDIENTE | L24: NINGUNO | M24: 203 | N24: NO | O24: NO | Q24: NO | S24: NO | U24: NO | V24: NO | W24: NO | X24: NO | Y24: NO | AA24: SI | AB24: NO | AE24: NO | AH24: NO | AK24: NO | AN24: NO | AO24: NO | AR24: 0 | AU24: NO | AV24: 2223339 | AW24: NO | AX24: NO | AY24: PORVENIR | AZ24: 30 | BA24: 2602824 | BB24: 0.16 | BC24: 416500 | BE24: 0 | BF24: 0 | BG24: 0 | BH24: 0 | BI24: 0 | BJ24: 416500 | BK24: NINGUNA | BL24: SALUD TOTAL | BM24: 30 | BN24: 2602824 | BO24: 0.04 | BP24: 104200 | BQ24: 0 | BS24: 0 | BU24: 0 | BV24: NINGUNA | BW24: COLMENA | BX24: 30 | BY24: 2602824 | BZ24: 0.0696 | CA24: 5 | CB24: CENTRO TRABAJO 30 | CC24: 5711001 | CD24: 181200 | CE24: 30 | CF24: COMFAMILIAR GUAJIRA | CG24: 2602824 | CH24: 0.04 | CI24: 104200 | CJ24: 2602824 | CK24: 0 | CL24: 0 | CM24: 0 | CN24: 0 | CO24: 0 | CP24: 0 | CQ24: 0 | CR24: 0 | CS24: SI
A25: CAUSADO | B25: CC | C25: 1006713857 | D25: PACHECO AGUDELO DANIEL JOSE | E25: PACHECO | F25: AGUDELO | G25: DANIEL | H25: JOSE | I25: LA_GUAJIRA | J25: RIOHACHA | K25: 1. DEPENDIENTE | L25: NINGUNO | M25: 204 | N25: NO | O25: NO | Q25: NO | S25: NO | U25: NO | V25: NO | W25: NO | X25: NO | Y25: NO | AA25: SI | AB25: NO | AE25: NO | AH25: NO | AK25: NO | AN25: NO | AO25: NO | AR25: 0 | AU25: NO | AV25: 1750905 | AW25: NO | AX25: NO | AY25: PORVENIR | AZ25: 30 | BA25: 2059702 | BB25: 0.16 | BC25: 329600 | BE25: 0 | BF25: 0 | BG25: 0 | BH25: 0 | BI25: 0 | BJ25: 329600 | BK25: NINGUNA | BL25: NUEVA E.P.S. | BM25: 30 | BN25: 2059702 | BO25: 0.04 | BP25: 82400 | BQ25: 0 | BS25: 0 | BU25: 0 | BV25: NINGUNA | BW25: COLMENA | BX25: 30 | BY25: 2059702 | BZ25: 0.0696 | CA25: 5 | CB25: CENTRO TRABAJO 30 | CC25: 5711001 | CD25: 143400 | CE25: 30 | CF25: COMFAMILIAR GUAJIRA | CG25: 2059702 | CH25: 0.04 | CI25: 82400 | CJ25: 2059702 | CK25: 0 | CL25: 0 | CM25: 0 | CN25: 0 | CO25: 0 | CP25: 0 | CQ25: 0 | CR25: 0 | CS25: SI
A26: CAUSADO | B26: CC | C26: 1006727380 | D26: CERVANTES MUÑOZ ONER DAVID | E26: CERVANTES | F26: MUÑOZ | G26: ONER | H26: DAVID | I26: BOGOTA_D.E. | J26: BOGOTA | K26: 1. DEPENDIENTE | L26: NINGUNO | M26: 0 | N26: NO | O26: NO | Q26: NO | S26: NO | U26: NO | V26: NO | W26: NO | X26: NO | Y26: NO | AA26: NO | AB26: LICENCIA NO REMUNERADA | AC26: 46054 | AD26: 46055 | AE26: NO | AH26: NO | AK26: NO | AN26: NO | AO26: NO | AR26: 0 | AU26: NO | AV26: 1750905 | AW26: NO | AX26: NO | AY26: PROTECCION | AZ26: 2 | BA26: 116727 | BB26: 0.16 | BC26: 18700 | BE26: 0 | BF26: 0 | BG26: 0 | BH26: 0 | BI26: 0 | BJ26: 18700 | BK26: NINGUNA | BL26: SALUD TOTAL | BM26: 2 | BN26: 116727 | BO26: 0 | BP26: 0 | BQ26: 0 | BS26: 0 | BU26: 0 | BV26: NINGUNA | BW26: COLMENA | BX26: 2 | BY26: 116727 | BZ26: 0 | CA26: 5 | CB26: CENTRO TRABAJO 24 | CC26: 5711001 | CD26: 0 | CE26: 2 | CF26: COMPENSAR | CG26: 0 | CH26: 0 | CI26: 0 | CJ26: 0 | CK26: 0 | CL26: 0 | CM26: 0 | CN26: 0 | CO26: 0 | CP26: 0 | CQ26: 0 | CR26: 0 | CS26: SI
A27: CAUSADO | B27: CC | C27: 1006727380 | D27: CERVANTES MUÑOZ ONER DAVID | E27: CERVANTES | F27: MUÑOZ | G27: ONER | H27: DAVID | I27: BOGOTA_D.E. | J27: BOGOTA | K27: 1. DEPENDIENTE | L27: NINGUNO | M27: 24 | N27: NO | O27: NO | Q27: NO | S27: Todos los sistemas (ARL, AFP, CCF, EPS) | T27: 46056 | U27: NO | V27: NO | W27: NO | X27: NO | Y27: NO | AA27: SI | AB27: NO | AE27: NO | AH27: NO | AK27: NO | AN27: NO | AO27: NO | AR27: 0 | AU27: NO | AV27: 1750905 | AW27: NO | AX27: NO | AY27: PROTECCION | AZ27: 1 | BA27: 721400 | BB27: 0.16 | BC27: 115500 | BE27: 0 | BF27: 0 | BG27: 0 | BH27: 0 | BI27: 0 | BJ27: 115500 | BK27: NINGUNA | BL27: SALUD TOTAL | BM27: 1 | BN27: 721400 | BO27: 0.04 | BP27: 28900 | BQ27: 0 | BS27: 0 | BU27: 0 | BV27: NINGUNA | BW27: COLMENA | BX27: 1 | BY27: 721400 | BZ27: 0.0696 | CA27: 5 | CB27: CENTRO TRABAJO 24 | CC27: 5711001 | CD27: 50300 | CE27: 1 | CF27: COMPENSAR | CG27: 1302414 | CH27: 0.04 | CI27: 52100 | CJ27: 1302414 | CK27: 0 | CL27: 0 | CM27: 0 | CN27: 0 | CO27: 0 | CP27: 0 | CQ27: 0 | CR27: 0 | CS27: SI
A28: CAUSADO | B28: CC | C28: 1006733914 | D28: CUEVA CONTRERAS EDAIR ALEJANDRO | E28: CUEVA | F28: CONTRERAS | G28: EDAIR | H28: ALEJANDRO | I28: LA_GUAJIRA | J28: RIOHACHA | K28: 1. DEPENDIENTE | L28: NINGUNO | M28: 205 | N28: NO | O28: NO | Q28: NO | S28: NO | U28: NO | V28: NO | W28: NO | X28: NO | Y28: NO | AA28: SI | AB28: NO | AE28: NO | AH28: NO | AK28: NO | AN28: NO | AO28: NO | AR28: 0 | AU28: NO | AV28: 1785595 | AW28: NO | AX28: NO | AY28: PORVENIR | AZ28: 30 | BA28: 2110655 | BB28: 0.16 | BC28: 337800 | BE28: 0 | BF28: 0 | BG28: 0 | BH28: 0 | BI28: 0 | BJ28: 337800 | BK28: NINGUNA | BL28: NUEVA E.P.S. | BM28: 30 | BN28: 2110655 | BO28: 0.04 | BP28: 84500 | BQ28: 0 | BS28: 0 | BU28: 0 | BV28: NINGUNA | BW28: COLMENA | BX28: 30 | BY28: 2110655 | BZ28: 0.0696 | CA28: 5 | CB28: CENTRO TRABAJO 30 | CC28: 5711001 | CD28: 147000 | CE28: 30 | CF28: COMFAMILIAR GUAJIRA | CG28: 2110655 | CH28: 0.04 | CI28: 84500 | CJ28: 2110655 | CK28: 0 | CL28: 0 | CM28: 0 | CN28: 0 | CO28: 0 | CP28: 0 | CQ28: 0 | CR28: 0 | CS28: SI
A29: CAUSADO | B29: CC | C29: 1006734131 | D29: GOMEZ ORTEGA JEINER JOSE | E29: GOMEZ | F29: ORTEGA | G29: JEINER | H29: JOSE | I29: LA_GUAJIRA | J29: RIOHACHA | K29: 1. DEPENDIENTE | L29: NINGUNO | M29: 0 | N29: NO | O29: NO | Q29: NO | S29: NO | U29: NO | V29: NO | W29: NO | X29: NO | Y29: NO | AA29: NO | AB29: NO | AE29: INCAPACIDAD GENERAL | AF29: 46055 | AG29: 46056 | AH29: NO | AK29: NO | AN29: NO | AO29: NO | AR29: 0 | AU29: NO | AV29: 2074908 | AW29: NO | AX29: NO | AY29: PORVENIR | AZ29: 2 | BA29: 162980 | BB29: 0.16 | BC29: 26100 | BE29: 0 | BF29: 0 | BG29: 0 | BH29: 0 | BI29: 0 | BJ29: 26100 | BK29: NINGUNA | BL29: NUEVA E.P.S. | BM29: 2 | BN29: 162980 | BO29: 0.04 | BP29: 6600 | BQ29: 0 | BS29: 0 | BU29: 0 | BV29: NINGUNA | BW29: COLMENA | BX29: 2 | BY29: 162980 | BZ29: 0 | CA29: 5 | CB29: CENTRO TRABAJO 30 | CC29: 5711001 | CD29: 0 | CE29: 2 | CF29: COMFAMILIAR GUAJIRA | CG29: 0 | CH29: 0 | CI29: 0 | CJ29: 0 | CK29: 0 | CL29: 0 | CM29: 0 | CN29: 0 | CO29: 0 | CP29: 0 | CQ29: 0 | CR29: 0 | CS29: SI
A30: CAUSADO | B30: CC | C30: 1006734131 | D30: GOMEZ ORTEGA JEINER JOSE | E30: GOMEZ | F30: ORTEGA | G30: JEINER | H30: JOSE | I30: LA_GUAJIRA | J30: RIOHACHA | K30: 1. DEPENDIENTE | L30: NINGUNO | M30: 184 | N30: NO | O30: NO | Q30: NO | S30: NO | U30: NO | V30: NO | W30: NO | X30: NO | Y30: NO | AA30: SI | AB30: NO | AE30: NO | AH30: NO | AK30: NO | AN30: NO | AO30: NO | AR30: 0 | AU30: NO | AV30: 2074908 | AW30: NO | AX30: NO | AY30: PORVENIR | AZ30: 28 | BA30: 2237443 | BB30: 0.16 | BC30: 358000 | BE30: 0 | BF30: 0 | BG30: 0 | BH30: 0 | BI30: 0 | BJ30: 358000 | BK30: NINGUNA | BL30: NUEVA E.P.S. | BM30: 28 | BN30: 2237443 | BO30: 0.04 | BP30: 89500 | BQ30: 0 | BS30: 0 | BU30: 0 | BV30: NINGUNA | BW30: COLMENA | BX30: 28 | BY30: 2237443 | BZ30: 0.0696 | CA30: 5 | CB30: CENTRO TRABAJO 30 | CC30: 5711001 | CD30: 155800 | CE30: 28 | CF30: COMFAMILIAR GUAJIRA | CG30: 2237443 | CH30: 0.04 | CI30: 89500 | CJ30: 2237443 | CK30: 0 | CL30: 0 | CM30: 0 | CN30: 0 | CO30: 0 | CP30: 0 | CQ30: 0 | CR30: 0 | CS30: SI
A31: CAUSADO | B31: CC | C31: 1006734275 | D31: BRITO BRITO NEIDER IVAN | E31: BRITO | F31: BRITO | G31: NEIDER | H31: IVAN | I31: LA_GUAJIRA | J31: RIOHACHA | K31: 1. DEPENDIENTE | L31: NINGUNO | M31: 205 | N31: NO | O31: NO | Q31: NO | S31: NO | U31: NO | V31: NO | W31: NO | X31: NO | Y31: NO | AA31: SI | AB31: NO | AE31: NO | AH31: NO | AK31: NO | AN31: NO | AO31: NO | AR31: 0 | AU31: NO | AV31: 1750905 | AW31: NO | AX31: NO | AY31: PORVENIR | AZ31: 30 | BA31: 2069651 | BB31: 0.16 | BC31: 331200 | BE31: 0 | BF31: 0 | BG31: 0 | BH31: 0 | BI31: 0 | BJ31: 331200 | BK31: NINGUNA | BL31: NUEVA E.P.S. | BM31: 30 | BN31: 2069651 | BO31: 0.04 | BP31: 82800 | BQ31: 0 | BS31: 0 | BU31: 0 | BV31: NINGUNA | BW31: COLMENA | BX31: 30 | BY31: 2069651 | BZ31: 0.0696 | CA31: 5 | CB31: CENTRO TRABAJO 30 | CC31: 5711001 | CD31: 144100 | CE31: 30 | CF31: COMFAMILIAR GUAJIRA | CG31: 2069651 | CH31: 0.04 | CI31: 82800 | CJ31: 2069651 | CK31: 0 | CL31: 0 | CM31: 0 | CN31: 0 | CO31: 0 | CP31: 0 | CQ31: 0 | CR31: 0 | CS31: SI
A32: CAUSADO | B32: CC | C32: 1006734430 | D32: MARTINEZ LARA CAMILO ENRIQUE | E32: MARTINEZ | F32: LARA | G32: CAMILO | H32: ENRIQUE | I32: LA_GUAJIRA | J32: RIOHACHA | K32: 1. DEPENDIENTE | L32: NINGUNO | M32: 0 | N32: NO | O32: NO | Q32: NO | S32: NO | U32: NO | V32: NO | W32: NO | X32: NO | Y32: NO | AA32: NO | AB32: LICENCIA NO REMUNERADA | AC32: 46054 | AD32: 46054 | AE32: NO | AH32: NO | AK32: NO | AN32: NO | AO32: NO | AR32: 0 | AU32: NO | AV32: 1750905 | AW32: NO | AX32: NO | AY32: PROTECCION | AZ32: 1 | BA32: 58364 | BB32: 0.16 | BC32: 9400 | BE32: 0 | BF32: 0 | BG32: 0 | BH32: 0 | BI32: 0 | BJ32: 9400 | BK32: NINGUNA | BL32: SANITAS | BM32: 1 | BN32: 58364 | BO32: 0 | BP32: 0 | BQ32: 0 | BS32: 0 | BU32: 0 | BV32: NINGUNA | BW32: COLMENA | BX32: 1 | BY32: 58364 | BZ32: 0 | CA32: 5 | CB32: CENTRO TRABAJO 30 | CC32: 5711001 | CD32: 0 | CE32: 1 | CF32: COMFAMILIAR GUAJIRA | CG32: 0 | CH32: 0 | CI32: 0 | CJ32: 0 | CK32: 0 | CL32: 0 | CM32: 0 | CN32: 0 | CO32: 0 | CP32: 0 | CQ32: 0 | CR32: 0 | CS32: SI
